[ERROR|base_events|L1758] 2024-05-23T15:59:20+0300: socket.accept() out of system resource
socket: <asyncio.TransportSocket fd=8, family=AddressFamily.AF_INET, type=SocketKind.SOCK_STREAM, proto=6, laddr=('0.0.0.0', 8000)>
Traceback (most recent call last):
  File "/usr/lib/python3.10/asyncio/selector_events.py", line 159, in _accept_connection
    conn, addr = sock.accept()
  File "/usr/lib/python3.10/socket.py", line 293, in accept
OSError: [Errno 24] Too many open files
[ERROR|base_events|L1758] 2024-05-23T15:59:20+0300: socket.accept() out of system resource
socket: <asyncio.TransportSocket fd=8, family=AddressFamily.AF_INET, type=SocketKind.SOCK_STREAM, proto=6, laddr=('0.0.0.0', 8000)>
Traceback (most recent call last):
  File "/usr/lib/python3.10/asyncio/selector_events.py", line 159, in _accept_connection
    conn, addr = sock.accept()
  File "/usr/lib/python3.10/socket.py", line 293, in accept
OSError: [Errno 24] Too many open files
[ERROR|base_events|L1758] 2024-05-23T15:59:20+0300: socket.accept() out of system resource
socket: <asyncio.TransportSocket fd=8, family=AddressFamily.AF_INET, type=SocketKind.SOCK_STREAM, proto=6, laddr=('0.0.0.0', 8000)>
Traceback (most recent call last):
  File "/usr/lib/python3.10/asyncio/selector_events.py", line 159, in _accept_connection
    conn, addr = sock.accept()
  File "/usr/lib/python3.10/socket.py", line 293, in accept
OSError: [Errno 24] Too many open files
[ERROR|base_events|L1758] 2024-05-23T15:59:20+0300: socket.accept() out of system resource
socket: <asyncio.TransportSocket fd=8, family=AddressFamily.AF_INET, type=SocketKind.SOCK_STREAM, proto=6, laddr=('0.0.0.0', 8000)>
Traceback (most recent call last):
  File "/usr/lib/python3.10/asyncio/selector_events.py", line 159, in _accept_connection
    conn, addr = sock.accept()
  File "/usr/lib/python3.10/socket.py", line 293, in accept
OSError: [Errno 24] Too many open files
[ERROR|base_events|L1758] 2024-05-23T15:59:20+0300: socket.accept() out of system resource
socket: <asyncio.TransportSocket fd=8, family=AddressFamily.AF_INET, type=SocketKind.SOCK_STREAM, proto=6, laddr=('0.0.0.0', 8000)>
Traceback (most recent call last):
  File "/usr/lib/python3.10/asyncio/selector_events.py", line 159, in _accept_connection
    conn, addr = sock.accept()
  File "/usr/lib/python3.10/socket.py", line 293, in accept
OSError: [Errno 24] Too many open files
[ERROR|base_events|L1758] 2024-05-23T15:59:20+0300: socket.accept() out of system resource
socket: <asyncio.TransportSocket fd=8, family=AddressFamily.AF_INET, type=SocketKind.SOCK_STREAM, proto=6, laddr=('0.0.0.0', 8000)>
Traceback (most recent call last):
  File "/usr/lib/python3.10/asyncio/selector_events.py", line 159, in _accept_connection
    conn, addr = sock.accept()
  File "/usr/lib/python3.10/socket.py", line 293, in accept
OSError: [Errno 24] Too many open files
[ERROR|base_events|L1758] 2024-05-23T15:59:20+0300: socket.accept() out of system resource
socket: <asyncio.TransportSocket fd=8, family=AddressFamily.AF_INET, type=SocketKind.SOCK_STREAM, proto=6, laddr=('0.0.0.0', 8000)>
Traceback (most recent call last):
  File "/usr/lib/python3.10/asyncio/selector_events.py", line 159, in _accept_connection
    conn, addr = sock.accept()
  File "/usr/lib/python3.10/socket.py", line 293, in accept
OSError: [Errno 24] Too many open files
[ERROR|base_events|L1758] 2024-05-23T15:59:20+0300: socket.accept() out of system resource
socket: <asyncio.TransportSocket fd=8, family=AddressFamily.AF_INET, type=SocketKind.SOCK_STREAM, proto=6, laddr=('0.0.0.0', 8000)>
Traceback (most recent call last):
  File "/usr/lib/python3.10/asyncio/selector_events.py", line 159, in _accept_connection
    conn, addr = sock.accept()
  File "/usr/lib/python3.10/socket.py", line 293, in accept
OSError: [Errno 24] Too many open files
[ERROR|base_events|L1758] 2024-05-23T15:59:20+0300: socket.accept() out of system resource
socket: <asyncio.TransportSocket fd=8, family=AddressFamily.AF_INET, type=SocketKind.SOCK_STREAM, proto=6, laddr=('0.0.0.0', 8000)>
Traceback (most recent call last):
  File "/usr/lib/python3.10/asyncio/selector_events.py", line 159, in _accept_connection
    conn, addr = sock.accept()
  File "/usr/lib/python3.10/socket.py", line 293, in accept
OSError: [Errno 24] Too many open files
[ERROR|base_events|L1758] 2024-05-23T15:59:20+0300: socket.accept() out of system resource
socket: <asyncio.TransportSocket fd=8, family=AddressFamily.AF_INET, type=SocketKind.SOCK_STREAM, proto=6, laddr=('0.0.0.0', 8000)>
Traceback (most recent call last):
  File "/usr/lib/python3.10/asyncio/selector_events.py", line 159, in _accept_connection
    conn, addr = sock.accept()
  File "/usr/lib/python3.10/socket.py", line 293, in accept
OSError: [Errno 24] Too many open files
[ERROR|base_events|L1758] 2024-05-23T15:59:20+0300: socket.accept() out of system resource
socket: <asyncio.TransportSocket fd=8, family=AddressFamily.AF_INET, type=SocketKind.SOCK_STREAM, proto=6, laddr=('0.0.0.0', 8000)>
Traceback (most recent call last):
  File "/usr/lib/python3.10/asyncio/selector_events.py", line 159, in _accept_connection
    conn, addr = sock.accept()
  File "/usr/lib/python3.10/socket.py", line 293, in accept
OSError: [Errno 24] Too many open files
[ERROR|base_events|L1758] 2024-05-23T15:59:20+0300: socket.accept() out of system resource
socket: <asyncio.TransportSocket fd=8, family=AddressFamily.AF_INET, type=SocketKind.SOCK_STREAM, proto=6, laddr=('0.0.0.0', 8000)>
Traceback (most recent call last):
  File "/usr/lib/python3.10/asyncio/selector_events.py", line 159, in _accept_connection
    conn, addr = sock.accept()
  File "/usr/lib/python3.10/socket.py", line 293, in accept
OSError: [Errno 24] Too many open files
[ERROR|base_events|L1758] 2024-05-23T15:59:20+0300: socket.accept() out of system resource
socket: <asyncio.TransportSocket fd=8, family=AddressFamily.AF_INET, type=SocketKind.SOCK_STREAM, proto=6, laddr=('0.0.0.0', 8000)>
Traceback (most recent call last):
  File "/usr/lib/python3.10/asyncio/selector_events.py", line 159, in _accept_connection
    conn, addr = sock.accept()
  File "/usr/lib/python3.10/socket.py", line 293, in accept
OSError: [Errno 24] Too many open files
[ERROR|base_events|L1758] 2024-05-23T15:59:20+0300: socket.accept() out of system resource
socket: <asyncio.TransportSocket fd=8, family=AddressFamily.AF_INET, type=SocketKind.SOCK_STREAM, proto=6, laddr=('0.0.0.0', 8000)>
Traceback (most recent call last):
  File "/usr/lib/python3.10/asyncio/selector_events.py", line 159, in _accept_connection
    conn, addr = sock.accept()
  File "/usr/lib/python3.10/socket.py", line 293, in accept
OSError: [Errno 24] Too many open files
[ERROR|base_events|L1758] 2024-05-23T15:59:20+0300: socket.accept() out of system resource
socket: <asyncio.TransportSocket fd=8, family=AddressFamily.AF_INET, type=SocketKind.SOCK_STREAM, proto=6, laddr=('0.0.0.0', 8000)>
Traceback (most recent call last):
  File "/usr/lib/python3.10/asyncio/selector_events.py", line 159, in _accept_connection
    conn, addr = sock.accept()
  File "/usr/lib/python3.10/socket.py", line 293, in accept
OSError: [Errno 24] Too many open files
[ERROR|base_events|L1758] 2024-05-23T15:59:20+0300: socket.accept() out of system resource
socket: <asyncio.TransportSocket fd=8, family=AddressFamily.AF_INET, type=SocketKind.SOCK_STREAM, proto=6, laddr=('0.0.0.0', 8000)>
Traceback (most recent call last):
  File "/usr/lib/python3.10/asyncio/selector_events.py", line 159, in _accept_connection
    conn, addr = sock.accept()
  File "/usr/lib/python3.10/socket.py", line 293, in accept
OSError: [Errno 24] Too many open files
[ERROR|base_events|L1758] 2024-05-23T15:59:20+0300: socket.accept() out of system resource
socket: <asyncio.TransportSocket fd=8, family=AddressFamily.AF_INET, type=SocketKind.SOCK_STREAM, proto=6, laddr=('0.0.0.0', 8000)>
Traceback (most recent call last):
  File "/usr/lib/python3.10/asyncio/selector_events.py", line 159, in _accept_connection
    conn, addr = sock.accept()
  File "/usr/lib/python3.10/socket.py", line 293, in accept
OSError: [Errno 24] Too many open files
[ERROR|base_events|L1758] 2024-05-23T15:59:20+0300: socket.accept() out of system resource
socket: <asyncio.TransportSocket fd=8, family=AddressFamily.AF_INET, type=SocketKind.SOCK_STREAM, proto=6, laddr=('0.0.0.0', 8000)>
Traceback (most recent call last):
  File "/usr/lib/python3.10/asyncio/selector_events.py", line 159, in _accept_connection
    conn, addr = sock.accept()
  File "/usr/lib/python3.10/socket.py", line 293, in accept
OSError: [Errno 24] Too many open files
[DEBUG|log_middleware|L13] 2024-05-23T15:59:20+0300: [(b'host', b'localhost:8000'), (b'upgrade', b'websocket'), (b'connection', b'Upgrade'), (b'sec-websocket-key', b'Fdfu8HuwJfu9Bz83U0AgxA=='), (b'sec-websocket-version', b'13'), (b'sec-websocket-extensions', b'permessage-deflate; client_max_window_bits'), (b'authorization', b'Bearer eyJhbGciOiJIUzI1NiIsInR5cCI6IkpXVCJ9.eyJpZCI6IjI4MTYyMDhlLTdkOGItNGRiZi05YjFmLTRmMjZjN2IzY2FiYSIsImlhdCI6MTcxNjQ2ODQyNCwiZXhwIjoxNzE2NDcyMDI0fQ.ykhQjFzOsP8Z-L0UcFWV_jzMOhb00SBLx3Du9Ocp4PI'), (b'user-agent', b'Python/3.10 websockets/12.0')]
[DEBUG|dependency_auth|L42] 2024-05-23T15:59:20+0300: Request for curr user id
[DEBUG|log_middleware|L13] 2024-05-23T15:59:20+0300: [(b'host', b'localhost:8000'), (b'upgrade', b'websocket'), (b'connection', b'Upgrade'), (b'sec-websocket-key', b'ThSXtP3Gu74tpUJvlqEwwQ=='), (b'sec-websocket-version', b'13'), (b'sec-websocket-extensions', b'permessage-deflate; client_max_window_bits'), (b'authorization', b'Bearer eyJhbGciOiJIUzI1NiIsInR5cCI6IkpXVCJ9.eyJpZCI6IjI4MTYyMDhlLTdkOGItNGRiZi05YjFmLTRmMjZjN2IzY2FiYSIsImlhdCI6MTcxNjQ2ODQyNCwiZXhwIjoxNzE2NDcyMDI0fQ.ykhQjFzOsP8Z-L0UcFWV_jzMOhb00SBLx3Du9Ocp4PI'), (b'user-agent', b'Python/3.10 websockets/12.0')]
[DEBUG|dependency_auth|L42] 2024-05-23T15:59:20+0300: Request for curr user id
